<?xml version="1.0" encoding="utf-8"?>

<robot name="guaraci">

  <link name="base">
    <visual>
      <!-- <origin rpy="0 0 1.5707" xyz="0 0 0" /> -->
      <origin rpy="1.5707 0 1.5707" xyz="0 0 0" />
      <geometry>
        <mesh filename="../meshes/body100.dae" scale="0.001 0.001 0.001"/>
      </geometry>
    </visual>
    <collision>
      <!-- <origin rpy="0 0 1.5707" xyz="0 0 0" /> -->
      <origin rpy="0 0 1.5707" xyz="0 0 0" />
      <geometry>
        <mesh filename="../meshes/body100.dae" scale="0.001 0.001 0.001"/>
      </geometry>
    </collision>
    <inertial>
      <mass value="9.42278" />
      <origin rpy="0 0 0" xyz="3.073e-05 0.0 2.577e-05" />
      <inertia ixx="0.05235" ixy="0" ixz="0" iyy="0.08538" iyz="0" izx="0" izz="0.1338"/>
    </inertial>
  </link>

  <link name="coxa_r1">
    <inertial>
      <mass value="0.59759" />
      <origin rpy="0 0 0" xyz="0 0 -3.357e-05" />
      <inertia ixx="0.00055" ixy="0" ixz="0" iyy="0.00124" iyz="0" izx="0" izz="0.00155"/>
    </inertial>
    <collision>
      <origin rpy="0 0 4.71229" xyz="0 0 0" />
      <geometry>
        <mesh filename="../meshes/coxa.dae" scale="0.001 0.001 0.001"/>
      </geometry>
    </collision>
    <visual>
      <origin rpy="0 0 4.71229" xyz="0 0 0" />
      <geometry>
        <mesh filename="../meshes/coxa.dae" scale="0.001 0.001 0.001"/>
      </geometry>
    </visual>
  </link>

  <joint name="joint_coxa_r1" type="revolute">
    <parent link="base" />
    <child link="coxa_r1" />
    <origin rpy="3.14159 0 2.35605" xyz="0.17302 0.10517 0" />
    <axis xyz="0 0 1"/>
    <limit effort="80.0" lower="-3.14159" upper="3.14159" velocity="20.0"/>
  </joint>

  <link name="coxa_r2">
    <inertial>
      <mass value="0.59759" />
      <origin rpy="0 0 0" xyz="0 0 -3.357e-05" />
      <inertia ixx="0.00055" ixy="0" ixz="0" iyy="0.00124" iyz="0" izx="0" izz="0.00155"/>
    </inertial>
    <collision>
      <origin rpy="0 0 4.71229" xyz="0 0 0" />
      <geometry>
        <mesh filename="../meshes/coxa.dae" scale="0.001 0.001 0.001"/>
      </geometry>
    </collision>
    <visual>
      <origin rpy="0 0 4.71229" xyz="0 0 0" />
      <geometry>
        <mesh filename="../meshes/coxa.dae" scale="0.001 0.001 0.001"/>
      </geometry>
    </visual>
  </link>

  <joint name="joint_coxa_r2" type="revolute">
    <parent link="base" />
    <child link="coxa_r2" />
    <origin rpy="3.14159 0 3.14159" xyz="0 0.169 0" />
    <axis xyz="0 0 1"/>
    <limit effort="80.0" lower="-3.14159" upper="3.14159" velocity="20.0"/>
  </joint>

  <link name="coxa_r3">
    <inertial>
      <mass value="0.59759" />
      <origin rpy="0 0 0" xyz="0 0 -3.357e-05" />
      <inertia ixx="0.00055" ixy="0" ixz="0" iyy="0.00124" iyz="0" izx="0" izz="0.00155"/>
    </inertial>
    <collision>
      <origin rpy="0 0 -1.5707" xyz="0 0 0" />
      <geometry>
        <mesh filename="../meshes/coxa.dae" scale="0.001 0.001 0.001"/>
      </geometry>
    </collision>
    <visual>
      <origin rpy="0 0 -1.5707" xyz="0 0 0" />
      <geometry>
        <mesh filename="../meshes/coxa.dae" scale="0.001 0.001 0.001"/>
      </geometry>
    </visual>
  </link>

  <joint name="joint_coxa_r3" type="revolute">
    <parent link="base" />
    <child link="coxa_r3" />
    <origin rpy="3.14159 0 3.92694" xyz="-0.17302 0.10517 0" />
    <axis xyz="0 0 1"/>
    <limit effort="80.0" lower="-3.14159" upper="3.14159" velocity="20.0"/>
  </joint>

  <link name="coxa_l1">
    <inertial>
      <mass value="0.59759" />
      <origin rpy="0 0 0" xyz="0 0 -3.357e-05" />
      <inertia ixx="0.00055" ixy="0" ixz="0" iyy="0.00124" iyz="0" izx="0" izz="0.00155"/>
    </inertial>
    <collision>
      <origin rpy="0 0 4.71229" xyz="0 0 0" />
      <geometry>
        <mesh filename="../meshes/coxa.dae" scale="0.001 0.001 0.001"/>
      </geometry>
    </collision>
    <visual>
      <origin rpy="0 0 4.71229" xyz="0 0 0" />
      <geometry>
        <mesh filename="../meshes/coxa.dae" scale="0.001 0.001 0.001"/>
      </geometry>
    </visual>
  </link>

  <joint name="joint_coxa_l1" type="revolute">
    <parent link="base" />
    <child link="coxa_l1" />
    <origin rpy="3.14159 0 7.0684" xyz="0.17302 -0.10517 0" />
    <axis xyz="0 0 1"/>
    <limit effort="80.0" lower="-3.14159" upper="3.14159" velocity="20.0"/>
  </joint>

  <link name="coxa_l2">
    <inertial>
      <mass value="0.59759" />
      <origin rpy="0 0 0" xyz="0 0 -3.357e-05" />
      <inertia ixx="0.00055" ixy="0" ixz="0" iyy="0.00124" iyz="0" izx="0" izz="0.00155"/>
    </inertial>
    <collision>
      <origin rpy="0 0 4.71229" xyz="0 0 0" />
      <geometry>
        <mesh filename="../meshes/coxa.dae" scale="0.001 0.001 0.001"/>
      </geometry>
    </collision>
    <visual>
      <origin rpy="0 0 4.71229" xyz="0 0 0" />
      <geometry>
        <mesh filename="../meshes/coxa.dae" scale="0.001 0.001 0.001"/>
      </geometry>
    </visual>
  </link>

  <joint name="joint_coxa_l2" type="revolute">
    <parent link="base" />
    <child link="coxa_l2" />
    <origin rpy="3.14159 0 6.28299" xyz="0 -0.169 0" />
    <axis xyz="0 0 1"/>
    <limit effort="80.0" lower="-3.14159" upper="3.14159" velocity="20.0"/>
  </joint>

  <link name="coxa_l3">
    <inertial>
      <mass value="0.59759" />
      <origin rpy="0 0 0" xyz="0 0 -3.357e-05" />
      <inertia ixx="0.00055" ixy="0" ixz="0" iyy="0.00124" iyz="0" izx="0" izz="0.00155"/>
    </inertial>
    <collision>
      <origin rpy="0 0 4.71229" xyz="0 0 0" />
      <geometry>
        <mesh filename="../meshes/coxa.dae" scale="0.001 0.001 0.001"/>
      </geometry>
    </collision>
    <visual>
      <origin rpy="0 0 4.71229" xyz="0 0 0" />
      <geometry>
        <mesh filename="../meshes/coxa.dae" scale="0.001 0.001 0.001"/>
      </geometry>
    </visual>
  </link>

  <joint name="joint_coxa_l3" type="revolute">
    <parent link="base" />
    <child link="coxa_l3" />
    <origin rpy="3.14159 0 5.4976" xyz="-0.17302 -0.10517 0" />
    <axis xyz="0 0 1"/>
    <limit effort="80.0" lower="-3.14159" upper="3.14159" velocity="20.0"/>
  </joint>

  <link name="femur_r1">
    <inertial>
      <mass value="0.92606" />
      <origin rpy="0 0 0" xyz="0 0 0" />
      <inertia ixx="0.00098" ixy="0" ixz="0" iyy="0.00506" iyz="0" izx="0" izz="0.00473"/>
    </inertial>
    <collision>
      <origin rpy="1.5707 0 3.14159" xyz="0 0 0" />
      <geometry>
        <mesh filename="../meshes/femur220.dae" scale="0.001 0.001 0.001"/>
      </geometry>
    </collision>
    <visual>
      <origin rpy="1.5707 0 3.14159" xyz="0 0 0" />
      <geometry>
        <mesh filename="../meshes/femur220.dae" scale="0.001 0.001 0.001"/>
      </geometry>
    </visual>
  </link>

  <joint name="joint_femur_r1" type="revolute">
    <parent link="coxa_r1" />
    <child link="femur_r1" />
    <origin rpy="1.5707 0 1.5707" xyz="0 0.09041 0" />
    <axis xyz="0 0 1"/>
    <limit effort="80.0" lower="-3.14159" upper="3.14159" velocity="20.0"/>
  </joint>

  <link name="femur_r2">
    <inertial>
      <mass value="0.92606" />
      <origin rpy="0 0 0" xyz="0 0 0" />
      <inertia ixx="0.00098" ixy="0" ixz="0" iyy="0.00506" iyz="0" izx="0" izz="0.00473"/>
    </inertial>
    <collision>
      <origin rpy="1.5707 0 3.14159" xyz="0 0 0" />
      <geometry>
        <mesh filename="../meshes/femur220.dae" scale="0.001 0.001 0.001"/>
      </geometry>
    </collision>
    <visual>
      <origin rpy="1.5707 0 3.14159" xyz="0 0 0" />
      <geometry>
        <mesh filename="../meshes/femur220.dae" scale="0.001 0.001 0.001"/>
      </geometry>
    </visual>
  </link>

  <joint name="joint_femur_r2" type="revolute">
    <parent link="coxa_r2" />
    <child link="femur_r2" />
    <origin rpy="1.5707 0 1.5707" xyz="0 0.09041 0" />
    <axis xyz="0 0 1"/>
    <limit effort="80.0" lower="-3.14159" upper="3.14159" velocity="20.0"/>
  </joint>

  <link name="femur_r3">
    <inertial>
      <mass value="0.92606" />
      <origin rpy="0 0 0" xyz="0 0 0" />
      <inertia ixx="0.00098" ixy="0" ixz="0" iyy="0.00506" iyz="0" izx="0" izz="0.00473"/>
    </inertial>
    <collision>
      <origin rpy="1.5707 0 3.14159" xyz="0 0 0" />
      <geometry>
        <mesh filename="../meshes/femur220.dae" scale="0.001 0.001 0.001"/>
      </geometry>
    </collision>
    <visual>
      <origin rpy="1.5707 0 3.14159" xyz="0 0 0" />
      <geometry>
        <mesh filename="../meshes/femur220.dae" scale="0.001 0.001 0.001"/>
      </geometry>
    </visual>
  </link>

  <joint name="joint_femur_r3" type="revolute">
    <parent link="coxa_r3" />
    <child link="femur_r3" />
    <origin rpy="1.5707 0 1.5707" xyz="0 0.09041 0" />
    <axis xyz="0 0 1"/>
    <limit effort="80.0" lower="-3.14159" upper="3.14159" velocity="20.0"/>
  </joint>

  <link name="femur_l1">
    <inertial>
      <mass value="0.92606" />
      <origin rpy="0 0 0" xyz="0 0 0" />
      <inertia ixx="0.00098" ixy="0" ixz="0" iyy="0.00506" iyz="0" izx="0" izz="0.00473"/>
    </inertial>
    <collision>
      <origin rpy="1.5707 0 3.14159" xyz="0 0 0" />
      <geometry>
        <mesh filename="../meshes/femur220.dae" scale="0.001 0.001 0.001"/>
      </geometry>
    </collision>
    <visual>
      <origin rpy="1.5707 0 3.14159" xyz="0 0 0" />
      <geometry>
        <mesh filename="../meshes/femur220.dae" scale="0.001 0.001 0.001"/>
      </geometry>
    </visual>
  </link>

  <joint name="joint_femur_l1" type="revolute">
    <parent link="coxa_l1" />
    <child link="femur_l1" />
    <origin rpy="1.5707 0 1.5707" xyz="0 0.09041 0" />
    <axis xyz="0 0 1"/>
    <limit effort="80.0" lower="-3.14159" upper="3.14159" velocity="20.0"/>
  </joint>

  <link name="femur_l2">
    <inertial>
      <mass value="0.92606" />
      <origin rpy="0 0 0" xyz="0 0 0" />
      <inertia ixx="0.00098" ixy="0" ixz="0" iyy="0.00506" iyz="0" izx="0" izz="0.00473"/>
    </inertial>
    <collision>
      <origin rpy="1.5707 0 3.14159" xyz="0 0 0" />
      <geometry>
        <mesh filename="../meshes/femur220.dae" scale="0.001 0.001 0.001"/>
      </geometry>
    </collision>
    <visual>
      <origin rpy="1.5707 0 3.14159" xyz="0 0 0" />
      <geometry>
        <mesh filename="../meshes/femur220.dae" scale="0.001 0.001 0.001"/>
      </geometry>
    </visual>
  </link>

  <joint name="joint_femur_l2" type="revolute">
    <parent link="coxa_l2" />
    <child link="femur_l2" />
    <origin rpy="1.5707 0 1.5707" xyz="0 0.09041 0" />
    <axis xyz="0 0 1"/>
    <limit effort="80.0" lower="-3.14159" upper="3.14159" velocity="20.0"/>
  </joint>
  
  <link name="femur_l3">
    <inertial>
      <mass value="0.92606" />
      <origin rpy="0 0 0" xyz="0 0 0" />
      <inertia ixx="0.00098" ixy="0" ixz="0" iyy="0.00506" iyz="0" izx="0" izz="0.00473"/>
    </inertial>
    <collision>
      <origin rpy="1.5707 0 3.14159" xyz="0 0 0" />
      <geometry>
        <mesh filename="../meshes/femur220.dae" scale="0.001 0.001 0.001"/>
      </geometry>
    </collision>
    <visual>
      <origin rpy="1.5707 0 3.14159" xyz="0 0 0" />
      <geometry>
        <mesh filename="../meshes/femur220.dae" scale="0.001 0.001 0.001"/>
      </geometry>
    </visual>
  </link>

  <joint name="joint_femur_l3" type="revolute">
    <parent link="coxa_l3" />
    <child link="femur_l3" />
    <origin rpy="1.5707 0 1.5707" xyz="0 0.09041 0" />
    <axis xyz="0 0 1"/>
    <limit effort="80.0" lower="-3.14159" upper="3.14159" velocity="20.0"/>
  </joint>

  <link name="tibia_r1">
    <inertial>
      <mass value="0.71403" />
      <origin rpy="0 0 0" xyz="0 0 0" />
      <inertia ixx="0.00097" ixy="0" ixz="0" iyy="0.00449" iyz="0" izx="0" izz="0.00383"/>
    </inertial>
    
    <visual>
      <origin rpy="1.5707 3.14159 0" xyz="0 0 0" />
      <geometry>
        <mesh filename="../meshes/tibia_3.dae" scale="0.001 0.001 0.001"/>
      </geometry>
    </visual>
  </link>

  <joint name="joint_tibia_r1" type="revolute">
    <parent link="femur_r1" />
    <child link="tibia_r1" />
    <origin rpy="0 0 0" xyz="0.220 0 0" />
    <axis xyz="0 0 1"/>
    <limit effort="80.0" lower="-3.14159" upper="3.14159" velocity="20.0"/>
  </joint>

  <link name="tibia_r2">
    <inertial>
      <mass value="0.71403" />
      <origin rpy="0 0 0" xyz="0 0 0" />
      <inertia ixx="0.00097" ixy="0" ixz="0" iyy="0.00449" iyz="0" izx="0" izz="0.00383"/>
    </inertial>
    
    <visual>
      <origin rpy="1.5707 3.14159 0" xyz="0 0 0" />
      <geometry>
        <mesh filename="../meshes/tibia_3.dae" scale="0.001 0.001 0.001"/>
      </geometry>
    </visual>
  </link>

  <joint name="joint_tibia_r2" type="revolute">
    <parent link="femur_r2" />
    <child link="tibia_r2" />
    <origin rpy="0 0 0" xyz="0.220 0 0" />
    <axis xyz="0 0 1"/>
    <limit effort="80.0" lower="-3.14159" upper="3.14159" velocity="20.0"/>
  </joint>

  <link name="tibia_r3">
    <inertial>
      <mass value="0.71403" />
      <origin rpy="0 0 0" xyz="0 0 0" />
      <inertia ixx="0.00097" ixy="0" ixz="0" iyy="0.00449" iyz="0" izx="0" izz="0.00383"/>
    </inertial>
    
    <visual>
      <origin rpy="1.5707 3.14159 0" xyz="0 0 0" />
      <geometry>
        <mesh filename="../meshes/tibia_3.dae" scale="0.001 0.001 0.001"/>
      </geometry>
    </visual>
  </link>

  <joint name="joint_tibia_r3" type="revolute">
    <parent link="femur_r3" />
    <child link="tibia_r3" />
    <origin rpy="0 0 0" xyz="0.220 0 0" />
    <axis xyz="0 0 1"/>
    <limit effort="80.0" lower="-3.14159" upper="3.14159" velocity="20.0"/>
  </joint>

  <link name="tibia_l1">
    <inertial>
      <mass value="0.71403" />
      <origin rpy="0 0 0" xyz="0 0 0" />
      <inertia ixx="0.00097" ixy="0" ixz="0" iyy="0.00449" iyz="0" izx="0" izz="0.00383"/>
    </inertial>
    
    <visual>
      <origin rpy="1.5707 3.14159 0" xyz="0 0 0" />
      <geometry>
        <mesh filename="../meshes/tibia_3.dae" scale="0.001 0.001 0.001"/>
      </geometry>
    </visual>
  </link>

  <joint name="joint_tibia_l1" type="revolute">
    <parent link="femur_l1" />
    <child link="tibia_l1" />
    <origin rpy="0 0 0" xyz="0.220 0 0" />
    <axis xyz="0 0 1"/>
    <limit effort="80.0" lower="-3.14159" upper="3.14159" velocity="20.0"/>
  </joint>

  <link name="tibia_l2">
    <inertial>
      <mass value="0.71403" />
      <origin rpy="0 0 0" xyz="0 0 0" />
      <inertia ixx="0.00097" ixy="0" ixz="0" iyy="0.00449" iyz="0" izx="0" izz="0.00383"/>
    </inertial>
    
    <visual>
      <origin rpy="1.5707 3.14159 0" xyz="0 0 0" />
      <geometry>
        <mesh filename="../meshes/tibia_3.dae" scale="0.001 0.001 0.001"/>
      </geometry>
    </visual>
  </link>

  <joint name="joint_tibia_l2" type="revolute">
    <parent link="femur_l2" />
    <child link="tibia_l2" />
    <origin rpy="0 0 0" xyz="0.220 0 0" />
    <axis xyz="0 0 1"/>
    <limit effort="80.0" lower="-3.14159" upper="3.14159" velocity="20.0"/>
  </joint>

  <link name="tibia_l3">
    <inertial>
      <mass value="0.71403" />
      <origin rpy="0 0 0" xyz="0 0 0" />
      <inertia ixx="0.00097" ixy="0" ixz="0" iyy="0.00449" iyz="0" izx="0" izz="0.00383"/>
    </inertial>
    
    <visual>
      <origin rpy="1.5707 3.14159 0" xyz="0 0 0" />
      <geometry>
        <mesh filename="../meshes/tibia_3.dae" scale="0.001 0.001 0.001"/>
      </geometry>
    </visual>
  </link>

  <joint name="joint_tibia_l3" type="revolute">
    <parent link="femur_l3" />
    <child link="tibia_l3" />
    <origin rpy="0 0 0" xyz="0.220 0 0" />
    <axis xyz="0 0 1"/>
    <limit effort="80.0" lower="-3.14159" upper="3.14159" velocity="20.0"/>
  </joint>

  <link name="r1_FOOT">
    <inertial>
      <mass value="1.15784" />
      <origin rpy="0 0 0" xyz="0 0 0" />
      <inertia ixx="0.001" ixy="0" ixz="0" iyy="0.00124" iyz="0" izx="0" izz="0.00096"/>
    </inertial>
    <collision>
            <origin xyz="0 0 0.0225"/>
            <geometry>
                <sphere radius="0.03"/>
            </geometry>
        </collision>
    <visual>
      <origin rpy="0 3.14159 0" xyz="0 0 0" />
      <geometry>
        <mesh filename="../meshes/foot.dae" scale="0.001 0.001 0.001"/>
      </geometry>
    </visual>
  </link>

  <joint name="joint_r1_FOOT" type="fixed">
    <parent link="tibia_r1" />
    <child link="r1_FOOT" />
    <origin rpy="1.5707 0 0" xyz="0.19859 0 0" />
    <!-- <axis xyz="0 0 1"/>
    <limit effort="80.0" lower="-3.14159" upper="3.14159" velocity="20.0"/> -->
  </joint>

  <link name="r2_FOOT">
    <inertial>
      <mass value="1.15784" />
      <origin rpy="0 0 0" xyz="0 0 0" />
      <inertia ixx="0.001" ixy="0" ixz="0" iyy="0.00124" iyz="0" izx="0" izz="0.00096"/>
    </inertial>
    <collision>
            <origin xyz="0 0 0.0225"/>
            <geometry>
                <sphere radius="0.03"/>
            </geometry>
        </collision>
    <visual>
      <origin rpy="0 3.14159 0" xyz="0 0 0" />
      <geometry>
        <mesh filename="../meshes/foot.dae" scale="0.001 0.001 0.001"/>
      </geometry>
    </visual>
  </link>

  <joint name="joint_r2_FOOT" type="fixed">
    <parent link="tibia_r2" />
    <child link="r2_FOOT" />
    <origin rpy="1.5707 0 0" xyz="0.19859 0 0" />
    <!-- <axis xyz="0 0 1"/>
    <limit effort="80.0" lower="-3.14159" upper="3.14159" velocity="20.0"/> -->
  </joint>

  <link name="r3_FOOT">
    <inertial>
      <mass value="1.15784" />
      <origin rpy="0 0 0" xyz="0 0 0" />
      <inertia ixx="0.001" ixy="0" ixz="0" iyy="0.00124" iyz="0" izx="0" izz="0.00096"/>
    </inertial>
    <collision>
            <origin xyz="0 0 0.0225"/>
            <geometry>
                <sphere radius="0.03"/>
            </geometry>
        </collision>
    <visual>
      <origin rpy="0 3.14159 0" xyz="0 0 0" />
      <geometry>
        <mesh filename="../meshes/foot.dae" scale="0.001 0.001 0.001"/>
      </geometry>
    </visual>
  </link>

  <joint name="joint_r3_FOOT" type="fixed">
    <parent link="tibia_r3" />
    <child link="r3_FOOT" />
    <origin rpy="1.5707 0 0" xyz="0.19859 0 0" />
    <!-- <axis xyz="0 0 1"/>
    <limit effort="80.0" lower="-3.14159" upper="3.14159" velocity="20.0"/> -->
  </joint>

  <link name="l1_FOOT">
    <inertial>
      <mass value="1.15784" />
      <origin rpy="0 0 0" xyz="0 0 0" />
      <inertia ixx="0.001" ixy="0" ixz="0" iyy="0.00124" iyz="0" izx="0" izz="0.00096"/>
    </inertial>
    <collision>
            <origin xyz="0 0 0.0225"/>
            <geometry>
                <sphere radius="0.03"/>
            </geometry>
        </collision>
    <visual>
      <origin rpy="0 3.14159 0" xyz="0 0 0" />
      <geometry>
        <mesh filename="../meshes/foot.dae" scale="0.001 0.001 0.001"/>
      </geometry>
    </visual>
  </link>

  <joint name="joint_l1_FOOT" type="fixed">
    <parent link="tibia_l1" />
    <child link="l1_FOOT" />
    <origin rpy="1.5707 0 0" xyz="0.19859 0 0" />
    <!-- <axis xyz="0 0 1"/>
    <limit effort="80.0" lower="-3.14159" upper="3.14159" velocity="20.0"/> -->
  </joint>

  <link name="l2_FOOT">
    <inertial>
      <mass value="1.15784" />
      <origin rpy="0 0 0" xyz="0 0 0" />
      <inertia ixx="0.001" ixy="0" ixz="0" iyy="0.00124" iyz="0" izx="0" izz="0.00096"/>
    </inertial>
    <collision>
            <origin xyz="0 0 0.0225"/>
            <geometry>
                <sphere radius="0.03"/>
            </geometry>
        </collision>
    <visual>
      <origin rpy="0 3.14159 0" xyz="0 0 0" />
      <geometry>
        <mesh filename="../meshes/foot.dae" scale="0.001 0.001 0.001"/>
      </geometry>
    </visual>
  </link>

  <joint name="joint_l2_FOOT" type="fixed">
    <parent link="tibia_l2" />
    <child link="l2_FOOT" />
    <origin rpy="1.5707 0 0" xyz="0.19859 0 0" />
    <!-- <axis xyz="0 0 1"/>
    <limit effort="80.0" lower="-3.14159" upper="3.14159" velocity="20.0"/> -->
  </joint>

  <link name="l3_FOOT">
    <inertial>
      <mass value="1.15784" />
      <origin rpy="0 0 0" xyz="0 0 0" />
      <inertia ixx="0.001" ixy="0" ixz="0" iyy="0.00124" iyz="0" izx="0" izz="0.00096"/>
    </inertial>
    <collision>
            <origin xyz="0 0 0.0225"/>
            <geometry>
                <sphere radius="0.03"/>
            </geometry>
        </collision>
    <visual>
      <origin rpy="0 3.14159 0" xyz="0 0 0" />
      <geometry>
        <mesh filename="../meshes/foot.dae" scale="0.001 0.001 0.001"/>
      </geometry>
    </visual>
  </link>

  <joint name="joint_l3_FOOT" type="fixed">
    <parent link="tibia_l3" />
    <child link="l3_FOOT" />
    <origin rpy="1.5707 0 0" xyz="0.19859 0 0" />
    <!-- <axis xyz="0 0 1"/>
    <limit effort="80.0" lower="-3.14159" upper="3.14159" velocity="20.0"/> -->
  </joint>

</robot>
